Workbook
Name _ITEM1: Comments!#REF!
Name _ITEM1: 'Specific Test Cases'!#REF!
Name _ITEM2: Comments!#REF!
Name _ITEM2: 'Specific Test Cases'!#REF!
Name _ITEM3: Comments!#REF!
Name _ITEM3: 'Specific Test Cases'!#REF!
Name _ITEM4: Comments!#REF!
Name _ITEM4: 'Specific Test Cases'!#REF!
Name _ITEM5: Comments!#REF!
Name _ITEM5: 'Specific Test Cases'!#REF!
Name _ITEM6: Comments!#REF!
Name _ITEM6: 'Specific Test Cases'!#REF!
Name Type: '[1]Maintenance Work Order'!#REF!

Sheet Report
D1: PARAMETER SHEET - REPORT
B2: MANUFACTURER NAME
B4: MODEL
B6: DEVICE TYPE
B8: USE CASE
B9: LPC 1.0.0
B10: ACTOR
B12: NAME OF TESTER(S)
B15: Overall Status
B16: Number of ATCs | E16: {=SUMPRODUCT(--ISNUMBER(SEARCH("ATC_",'Specific Test Cases'!B42:B191)))} -> 51
C17: Number of ATCs for the EG | E17: {=SUMPRODUCT(ISNUMBER(SEARCH("ATC_", 'Specific Test Cases'!B42:B191)) * ISNUMBER(SEARCH("EG", 'Specific Test Cases'!B42:B191)))} -> 8
C18: Number of ATCs for the CS | E18: {=SUMPRODUCT(ISNUMBER(SEARCH("ATC_", 'Specific Test Cases'!B42:B191)) * ISNUMBER(SEARCH("CS", 'Specific Test Cases'!B42:B191)))} -> 43
B19: Number of STCs | E19: {=SUMPRODUCT(--ISNUMBER(VALUE('Specific Test Cases'!B42:B191)))} -> 99
C20: Number of STCs for the EG | E20: {=SUMPRODUCT(--ISNUMBER(VALUE('Specific Test Cases'!B42:B64)))} -> 15
C21: Number of STCs for the CS | E21: {=SUMPRODUCT(--ISNUMBER(VALUE('Specific Test Cases'!B64:B191)))} -> 85
B22: Test cycle duration | E22: =TEXT(MAX('Specific Test Cases'!C42:C191)-MIN('Specific Test Cases'!C42:C191),"0") & " Tage" -> 0 Tage
B24: Execution Status
B25: Number of STCs executed | E25: {=SUMPRODUCT((('Specific Test Cases'!S42:S191="Passed")+('Specific Test Cases'!S42:S191="Failed"))*1)} -> 0
C26: Number of passed STCs | E26: =COUNTIF('Specific Test Cases'!S42:S191,"Passed") -> 0
B27: Passed percentace | E27: =IF(OR(E26=0,E25=0),0,E26/E25) -> 0
C28: Number of failed STCs | E28: =COUNTIF('Specific Test Cases'!S42:S191,"Failed") -> 0
B29: Failed percentage | E29: =IF(OR(E28=0,E25=0),0,E28/E25) -> 0
C30: Number of not applicable STCs | E30: =COUNTIF('Specific Test Cases'!S42:S191,"Not applicable") -> 0
B31: Not applicable percentace | E31: =IF(OR(E30=0,E19=0),0,E30/E19) -> 0
B33: Approval
B34: Approved by
B35: Date
B36: Signature

Sheet Specific Test Cases
D1: PARAMETER SHEET - SPECIFIC TEST CASES
B2: TECHNOLOGY | D2: e.g. SPINE
B3: CS type CEM?
B5: STARTUP DURATION [seconds]
B6: StartUpDur_EG
B7: StartUpDur_CS
B9: ACTIVE POWER CONSUMPTION LIMIT [Watt] | F9: CONSTRAINTS
B10: APCLmin | D10: 0 | F10: 0 ≤ APCL_min < APCL_max
B11: APCLmax | D11: 0.1 | F11: 0 ≤ APCL_min < APCL_max
C12: delta | D12: =0.05*(D11-D10) -> 0.005
B13: APCL_01 | D13: =IF((D10-D12)>0,D10-D12,0) -> 0 | F13: 0 ≤ APCL_01 < APCL_02 < APCL_03 < APCL_04 < APCL_05
B14: APCL_02 | D14: =D10+D12 -> 0.005 | F14: 0 ≤ APCL_01 < APCL_02 < APCL_03 < APCL_04 < APCL_05
B15: APCL_03 | F15: 0 ≤ APCL_01 < APCL_02 < APCL_03 < APCL_04 < APCL_05
B16: APCL_04 | D16: =D11-D12 -> 0.095 | F16: 0 ≤ APCL_01 < APCL_02 < APCL_03 < APCL_04 < APCL_05
B17: APCL_05 | D17: =D11+D12 -> 0.105 | F17: 0 ≤ APCL_01 < APCL_02 < APCL_03 < APCL_04 < APCL_05
B18: APCL_06 | D18: -1000
B19: FAILSAFE CONSUMPTION ACTIVE POWER LIMIT [Watt] | F19: CONSTRAINTS
B20: PFCAPL | F20: 0 ≤ PFCAPL
B21: FCAPLmin | D21: 0 | F21: 0 ≤ FCAPL_min < FCAPL_max
B22: FCAPLmax | D22: 0.1 | F22: 0 ≤ FCAPL_min < FCAPL_max
C23: delta | D23: =0.05*(D22-D21) -> 0.005
B24: FCAPL_01 | D24: =IF((D21-D23)>0,D21-D23,0) -> 0 | F24: 0 ≤ FCAPL_01 < FCAPL_02 < FCAPL_03 < FCAPL_04 < FCAPL_05
B25: FCAPL_02 | D25: =D21+D23 -> 0.005 | F25: 0 ≤ FCAPL_01 < FCAPL_02 < FCAPL_03 < FCAPL_04 < FCAPL_05
B26: FCAPL_03 | F26: 0 ≤ FCAPL_01 < FCAPL_02 < FCAPL_03 < FCAPL_04 < FCAPL_05
B27: FCAPL_04 | D27: =D22-D23 -> 0.095 | F27: 0 ≤ FCAPL_01 < FCAPL_02 < FCAPL_03 < FCAPL_04 < FCAPL_05
B28: FCAPL_05 | D28: =D22+D23 -> 0.105 | F28: 0 ≤ FCAPL_01 < FCAPL_02 < FCAPL_03 < FCAPL_04 < FCAPL_05
B29: FCAPL_06 | D29: -1000
B30: FAILSAFE DURATION MINIMUM [h[m[s]]] | F30: CONSTRAINTS
B31: MFSDM | F31: 2h ≤ PFSDM < MFSDM
B32: PFSDM | F32: 2h ≤ PFSDM < MFSDM
B33: FCAPL_DUR_01 | D33: 1h54m
B34: FCAPL_DUR_02 | F34: PFSDM < FCAPL_DUR_02 < MFSDM
B35: FCAPL_DUR_03 | D35: =1.05*D31 -> 0 | F35: 1.05 * MFSDM
B36: POWER CONSUMPTION NOMINAL MAX [Watt] | F36: CONSTRAINTS
B37: Value | F37: 0 < Power Consumption Nominal Max
B38: CONTRACTUAL CONSUMPTION NOMINAL MAX [Watt] | F38: CONSTRAINTS
B39: Value | F39: 0 < Contractual Consumption Nominal Max
B41: STC ID | C41: TEST DATE | D41: APCL USED IN TEST STEP | E41: ACTIVE POWER CONSUMPTION LIMIT - APCL [Watt] | G41: MESSAGE COMBINATIONS | H41: ACTIVE POWER CONSUMPTION LIMIT DURATION [seconds] | J41: FCAPL USED IN TEST STEP | K41: FAILSAFE CONSUMPTION ACTIVE POWER LIMIT - FCAPL [Watt] | M41: FAILSAFE DURATION MINIMUM USED IN TEST STEP | N41: FAILSAFE DURATION MINIMUM [h[m[s]]] | P41: POWER CONSUMPTION NOMINAL MAX [Watt] | Q41: CONTRACTUAL CONSUMPTION NOMINAL MAX [Watt] | R41: STARTUP DURATION [seconds] | S41: TEST VERDICT | T41: COMMENTS / NOTES / ADDITIONS
B42: ATC_COM_PT_EGHeartbeat_001
B43: 1
...

Sheet Optional Support
D1: PARAMETER SHEET - OPTIONAL SUPPORT
B2: Manufacturer statements on the support of optional protocol functionality.
B3: NO. | C3: SUPPORTED? [Yes/No] | D3: ACTOR | E3: FUNCTIONALITY | F3: SCENARIO | G3: MANDATORY ATC TO VERIFY STATEMENT | H3: COMMENTS
B4: A1 | D4: Energy Guard | E4: read/write APCL (value, activation flag, duration) | F4: 1 | G4: ATC_COM_PT_EGMessages_003
B5: A2 | D5: Energy Guard | E5: read/write FCAPL and Failsafe Duration Minimum | F5: 2 | G5: ATC_COM_PT_EGMessages_004
B6: A3 | D6: Energy Guard | E6: read Power Consumption Nominal Max | F6: 4 | G6: -
B7: A4 | D7: Energy Guard | E7: read Contractual Consumption Nominal Max | F7: 4 | G7: -
B8: A5 | D8: Energy Guard | E8: quick resend write APCL if previous write APCL was rejected | F8: 1 | G8: ATC_COM_PT_EGMessages_002
B9: A6 | D9: Energy Guard | E9: ongoing adjustment of CS' limit parameters | F9: 1, 2 | G9: ATC_COM_PT_EGMessages_003, ATC_COM_PT_EGMessages_004
B11: B1 | D11: Controllable System at "LPC instance 1" | E11: report of Contractual Consumption Nominal Max | F11: 4 | G11: ATC_COM_PT_CSUnlCntrl_002 | H11: Note: only works in conjunction with B2
B12: B2 | D12: Controllable System at "LPC instance 1" | E12: no report of Power Consumption Nominal Max | F12: 4 | G12: ATC_COM_PT_CSUnlCntrl_002 | H12: Note: only works in conjunction with B1
B13: B3 | D13: Controllable System at "LPC instance 1" | E13: permitted rejection of received APCL write command | F13: 1 | G13: ATC_INS1_PT_CSTransition1_001
B15: C1 | D15: Controllable System at "LPC instance 2" | E15: report of Power Consumption Nominal Max | F15: 4 | G15: ATC_COM_PT_CSUnlCntrl_003 | H15: Note: only works in conjunction with C2
B16: C2 | D16: Controllable System at "LPC instance 2" | E16: no report of Contractual Consumption Nominal Max | F16: 4 | G16: ATC_COM_PT_CSUnlCntrl_003 | H16: Note: only works in conjunction with C1
B17: C3 | D17: Controllable System at "LPC instance 2" | E17: permitted rejection of received APCL write command | F17: 1 | G17: ATC_INS2_PT_CSTransition1_001
B19: D1 | D19: Controllable System at any LPC instance | E19: auto-adjust too large received APCL | F19: 1 | G19: ATC_COM_PT_CSConnection_006
B20: D2 | D20: Controllable System at any LPC instance | E20: state "unlimited/autonomous" implemented | F20: 1, 2, 3 | G20: ATC_COM_NT_CSUnlAuto_001, ATC_COM_PT_CSTransition3_001, ATC_COM_PT_CSTransition3_002, ATC_COM_PT_CSTransition10_001, ATC_COM_PT_CSTransition10_002, ATC_COM_PT_CSTransition11_001, ATC_COM_PT_CSTransition11_002, ATC_COM_PT_CSTransition12_001
B22: E1 | D22: Energy Guard | E22: black start | F22: - | G22: ATC_COM_PT_EGConnection_003
B23: E2 | D23: Controllable System at any LPC instance | E23: black start | F23: - | G23: ATC_COM_PT_CSConnection_008
B25: Supplementary optional verifications
B26: NO. | C26: VERIFY? [Yes/No] | D26: ACTOR | E26: FUNCTIONALITY | F26: SCENARIO | G26: MANDATORY ATC TO VERIFY STATEMENT | H26: COMMENTS
B27: M1 | D27: Controllable System at "LPC instance 1" | E27: limit consumption according to Contractual Consumption Nominal Max | F27: 4 | G27: ATC_COM_NT_CSUnlAuto_002 | H27: Note: only works in conjunction with N1 and requires B1
B29: N1 | D29: Controllable System at "LPC instance 2" | E29: limit consumption according to Power Consumption Nominal Max | F29: 4 | G29: ATC_COM_NT_CSUnlAuto_002 | H29: Note: only works in conjunction with M1 and requires C1
B31: Legend
B32: read "X" | D32: Get value of "X" of the other actor.
B33: write "X" | D33: Set new/changed value of "X" of the other actor or delete "X".
B34: report "X" | D34: The actor owning "X" sends the value of "X" to the other actor.

Sheet Comments
D1: PARAMETER SHEET - COMMENTS
B2: TEST NO. | C2: TEST DATE | D2: GENERAL QUESTIONS / COMMENTS

Sheet Legend
D1: PARAMETER SHEET - LEGEND
B2: Revisions
B3: Version | D3: Date/Editor
B4: V1.0.0 | D4: 2024-06-10 - SH
B6: Specific Test Cases
D7: Cells with a white background need to be manually filled in with device specific information or information taken from the test specification.
D8: Greyed-out cells are filled in automatically.
B9: Formatting rules
D10: The cell background in which the values for APCLmax and FCAPLmax are entered turns red for visual support when entering wrong values or values in a wrong range. In addition, the cell of the calculated delta is coloured red in this case.
C11: Test verdict | D11: According to the chosen test verdict its background is colorized. [PASSED/FAILED/NOT APPLICABLE]
D12: Passed
D13: Failed
D14: Not applicable
B16: Optional Support
B17: Supported/Verify? [Yes/No] | D17: Use the drop-down menu to select whether the corresponding ATCs are also to be tested. These ATCs are then to be tested with defined data as STCs. [YES/NO]
