Workbook
Name _ITEM1: Comments!#REF!
Name _ITEM1: 'Specific Test Cases'!#REF!
Name _ITEM2: Comments!#REF!
Name _ITEM2: 'Specific Test Cases'!#REF!
Name _ITEM3: Comments!#REF!
Name _ITEM3: 'Specific Test Cases'!#REF!
Name _ITEM4: Comments!#REF!
Name _ITEM4: 'Specific Test Cases'!#REF!
Name _ITEM5: Comments!#REF!
Name _ITEM5: 'Specific Test Cases'!#REF!
Name _ITEM6: Comments!#REF!
Name _ITEM6: 'Specific Test Cases'!#REF!
Name Type: '[1]Maintenance Work Order'!#REF!

Sheet Report
D1: PARAMETER SHEET - REPORT
B2: MANUFACTURER NAME
B4: MODEL
B6: DEVICE TYPE
B8: USE CASE
B9: MPC 1.0.0
B10: ACTOR
B12: NAME OF TESTER(S)
B15: Overall Status
B16: Number of ATCs | E16: {=SUMPRODUCT(--ISNUMBER(SEARCH("ATC_",'Specific Test Cases'!B58:B255)))} -> 54
C17: Number of ATCs for the MU | E17: {=SUMPRODUCT(ISNUMBER(SEARCH("ATC_", 'Specific Test Cases'!B58:B255)) * ISNUMBER(SEARCH("MU", 'Specific Test Cases'!B58:B255)))} -> 20
C18: Number of ATCs for the MA | E18: {=SUMPRODUCT(ISNUMBER(SEARCH("ATC_", 'Specific Test Cases'!B58:B255)) * ISNUMBER(SEARCH("MA", 'Specific Test Cases'!B58:B255)))} -> 34
B19: Number of STCs | E19: {=SUMPRODUCT(--ISNUMBER(VALUE('Specific Test Cases'!B58:B255)))} -> 144
C20: Number of STCs for the MU | E20: {=SUMPRODUCT(--ISNUMBER(VALUE('Specific Test Cases'!B58:B127)))} -> 50
C21: Number of STCs for the MA | E21: {=SUMPRODUCT(--ISNUMBER(VALUE('Specific Test Cases'!B128:B255)))} -> 94
B22: Test cycle duration | E22: =TEXT(MAX('Specific Test Cases'!C58:C255)-MIN('Specific Test Cases'!C58:C255),"0") & " Tage" -> 0 Tage
B24: Execution Status
B25: Number of STCs executed | E25: {=SUMPRODUCT((('Specific Test Cases'!K58:K255="Passed")+('Specific Test Cases'!K58:K255="Failed"))*1)} -> 0
C26: Number of passed STCs | E26: =COUNTIF('Specific Test Cases'!K58:K255,"Passed") -> 0
B27: Passed percentace | E27: =IF(OR(E26=0,E25=0),0,E26/E25) -> 0
C28: Number of failed STCs | E28: =COUNTIF('Specific Test Cases'!K58:K255,"Failed") -> 0
B29: Failed percentage | E29: =IF(OR(E28=0,E25=0),0,E28/E25) -> 0
C30: Number of not applicable STCs | E30: =COUNTIF('Specific Test Cases'!K58:K255,"Not applicable") -> 0
B31: Not applicable percentace | E31: =IF(OR(E30=0,E19=0),0,E30/E19) -> 0
B33: Approval
B34: Approved by
B35: Date
B36: Signature

Sheet Specific Test Cases
D1: PARAMETER SHEET - SPECIFIC TEST CASES
B2: TECHNOLOGY | D2: e.g. SPINE
B4: DATA TRANSMISSION
D5: Usage | E5: Interval [seconds]
B6: Polling
B7: Notification
B9: CONNECTED PHASES
B10: Phase A
B11: Phase B
B12: Phase C
B14: SUPPORTED DATA POINTS
B15: Total Active Power
B16: Phase-Specific Active Power
B17: Total Consumed Energy
B18: Total Produced Energy
B19: Phase-Specific AC Current
... B21: AC Frequency
D23: ENERGY DIRECTION | E23: RANGES OF THE DUT
B24: TOTAL ACTIVE POWER [Watt] | E24: MIN | F24: MAX
B25: Power total | D25: consume
D26: produce
B27: PHASE-SPECIFIC ACTIVE POWER [Watt] | E27: MIN | F27: MAX
B28: Phase A | D28: consume
D29: produce
B30: Phase B | D30: consume
D31: produce
B32: Phase C | D32: consume
D33: produce
B34: TOTAL CONSUMED ENERGY [Watt] | E34: MIN | F34: MAX
B35: Total consumed energy | D35: consume
D36: produce | E36: =IF(E39="","",E39) | F36: =IF(F39="","",F39)
B37: TOTAL PRODUCED ENERGY [Watt] | E37: MIN | F37: MAX
B38: Total produced energy | D38: consume | E38: =IF(E35="","",E35) | F38: =IF(F35="","",F35)
D39: produce
B40: PHASE-SPECIFIC AC CURRENT [Ampere] | E40: MIN | F40: MAX
B41: Phase A | D41: consume
D42: produce
B43: Phase B | D43: consume
D44: produce
B45: Phase C | D45: consume
...

Sheet Comments
D1: PARAMETER SHEET - COMMENTS
B2: TEST NO. | C2: TEST DATE | D2: GENERAL QUESTIONS / COMMENTS

Sheet Legend
D1: PARAMETER SHEET - LEGEND
B2: Revisions
B3: Version | D3: Date/Editor
B4: V1.0.0 | D4: 2024-04-30 - SH
B6: Specific Test Cases
D7: Cells with a white background need to be manually filled in with device specific information or information taken from the test specification.
D8: Greyed-out cells are filled in automatically.
B9: Data transmission | D9: Use the drop-down menu to select whether the DUT uses polling or notification. [YES/NO]
B10: Supported data points | D10: Use the drop-down menu to select which data point is supported by the DUT. [YES/NO]
B11: Data point values | D11: The corresponding data point values shall be filled in as follows: MU as DUT: The value received by the tester. (Optional: Compare the read value with the MU display.) MA as DUT: The received value of the MA. (Mandatory: Compare the read value with the tester display.)
B12: any | D12: Don't care
B13: Formatting rules
C14: Test verdict | D14: According to the chosen test verdict its background is colorized. [PASSED/FAILED/NOT APPLICABLE]
D15: Passed
D16: Failed
D17: Not applicable
